<?xml version="1.0" ?>

<robot name="mycar" xmlns:xacro="http://www.ros.org/wiki/xacro" >

  <!-- colors/materials -->  
  <material name="black">
    <color rgba="0.0 0.0 0.0 1.0" />
  </material>  
  <material name="blue">
    <color rgba="0.203125 0.23828125 0.28515625 1.0" />
  </material>
  <material name="green">
    <color rgba="0.0 0.8 0.0 1.0" />
  </material>
  <material name="grey">
    <color rgba="0.2 0.2 0.2 1.0" />
  </material>
  <material name="orange">
    <color rgba="1.0 0.423529411765 0.0392156862745 1.0" />
  </material>
  <material name="brown">
    <color rgba="0.870588235294 0.811764705882 0.764705882353 1.0" />
  </material>
  <material name="red">
    <color rgba="0.80078125 0.12890625 0.1328125 1.0" />
  </material>
  <material name="white">
    <color rgba="1.0 1.0 1.0 1.0" />
  </material>

  <gazebo reference="chassis_link">
    <material>Gazebo/Orange</material>
  </gazebo>
  <gazebo reference="left_steer_block_link">
    <material>Gazebo/Orange</material>
  </gazebo>
  <gazebo reference="right_steer_block_link">
    <material>Gazebo/Orange</material>
  </gazebo>
  <gazebo reference="left_rear_wheel_link">
    <material>Gazebo/Blue</material>
  </gazebo>
  <gazebo reference="right_rear_wheel_link">
    <material>Gazebo/Blue</material>
  </gazebo>
  <gazebo reference="right_front_wheel_link">
    <material>Gazebo/Blue</material>
  </gazebo>
  <gazebo reference="left_front_wheel_link">
    <material>Gazebo/Blue</material>
  </gazebo>

  <!-- gazebo plugin -->
  <gazebo>
    <plugin name="gazebo_ros_control" filename="libgazebo_ros_control.so">
      <robotNamespace>/ackermann</robotNamespace>
    </plugin>
  </gazebo>

  <!-- joint controllers -->
  <transmission name="left_rear_wheel_trans">
    <type>transmission_interface/SimpleTransmission</type>
    <actuator name="motor_left" >
      <hardwareInterface>hardware_interface/EffortJointInterface</hardwareInterface>
      <mechanicalReduction>1</mechanicalReduction>
    </actuator>
    <joint name="left_rear_wheel_joint">
      <hardwareInterface>hardware_interface/EffortJointInterface</hardwareInterface>
    </joint>
  </transmission>

  <transmission name="right_rear_wheel_trans">
    <type>transmission_interface/SimpleTransmission</type>
    <actuator name="motor_right" >
      <hardwareInterface>hardware_interface/EffortJointInterface</hardwareInterface>
      <mechanicalReduction>1</mechanicalReduction>
    </actuator>
    <joint name="right_rear_wheel_joint">
      <hardwareInterface>hardware_interface/EffortJointInterface</hardwareInterface>
    </joint>
  </transmission>

  <transmission name="left_steer_block_trans">
    <type>transmission_interface/SimpleTransmission</type>
    <actuator name="left_steer" >
      <hardwareInterface>hardware_interface/EffortJointInterface</hardwareInterface>
      <mechanicalReduction>1</mechanicalReduction>
    </actuator>
    <joint name="left_steer_block_joint">
      <hardwareInterface>hardware_interface/EffortJointInterface</hardwareInterface>
    </joint>
  </transmission>

  <transmission name="right_steer_block_trans">
    <type>transmission_interface/SimpleTransmission</type>
    <actuator name="right_steer" >
      <hardwareInterface>hardware_interface/EffortJointInterface</hardwareInterface>
      <mechanicalReduction>1</mechanicalReduction>
    </actuator>
    <joint name="right_steer_block_joint">
      <hardwareInterface>hardware_interface/EffortJointInterface</hardwareInterface>
    </joint>
  </transmission>

    <!-- links -->
    <link name='chassis_link'>
      <inertial>
        <mass value="0.0945291" />
        <origin rpy="0 0 0" xyz="0 -0.342857 0" />
        <inertia ixx="0.00808473" ixy="0" ixz="0" iyy="0.00288146" iyz="0" izz="0.0105516" />
      </inertial>
      <collision name='chassis_collision'>
        <origin rpy="0 0 0" xyz="0 -0.342857 0" />
        <geometry>
          <box size="0.582641 1 0.162223" />
        </geometry>
      </collision>
      <visual name='chassis_visual'>
        <origin rpy="0 0 0" xyz="0 -0.342857 0" />
        <geometry>
          <box size="0.582641 1 0.162223" />
        </geometry>    
      </visual>
    </link>

    <link name='left_rear_wheel_link'>
      <inertial>
        <mass value="0.0196261" />
        <origin rpy="0 1.57079 0" xyz="0 0 0" />
        <inertia ixx="0.00028435" ixy="0" ixz="0" iyy="0.00028435" iyz="0" izz="0.00054297" />
      </inertial>
      <visual name='left_rear_wheel_visual'>
        <origin rpy="0 1.57079 0" xyz="0 0 0" />
        <geometry>
          <cylinder radius="0.235227" length="0.0886945" />
        </geometry>
      </visual>
      <collision name='left_rear_wheel_collision'>
        <origin rpy="0 1.57079 0" xyz="0 0 0" />
        <geometry>
          <cylinder radius="0.235227" length="0.0886945" />
        </geometry>
      </collision>
    </link>

    <link name='right_rear_wheel_link'>
      <inertial>
        <mass value="0.0196261" />
        <origin rpy="0 1.57079 0" xyz="0 0 0" />
        <inertia ixx="0.00028435" ixy="0" ixz="0" iyy="0.00028435" iyz="0" izz="0.00054297" />
      </inertial>
      <visual name='right_rear_wheel_visual'>
        <origin rpy="0 1.57079 0" xyz="0 0 0" />
        <geometry>
          <cylinder radius="0.235227" length="0.0886945" />
        </geometry>
      </visual>
      <collision name='right_rear_wheel_collision'>
        <origin rpy="0 1.57079 0" xyz="0 0 0" />
        <geometry>
          <cylinder radius="0.235227" length="0.0886945" />
        </geometry>
      </collision>
    </link>

    <link name='right_front_wheel_link'>
      <inertial>
        <mass value="0.0196261" />
        <origin rpy="0 1.57079 0" xyz="0 0 0" />
        <inertia ixx="0.00028435" ixy="0" ixz="0" iyy="0.00028435" iyz="0" izz="0.00054297" />
      </inertial>
      <visual name='right_front_wheel_visual'>
        <origin rpy="0 1.57079 0" xyz="0 0 0" />
        <geometry>
          <cylinder radius="0.235227" length="0.0886945" />
        </geometry>
      </visual>
      <collision name='right_front_wheel_collision'>
        <origin rpy="0 1.57079 0" xyz="0 0 0" />
        <geometry>
          <cylinder radius="0.235227" length="0.0886945" />
        </geometry>
      </collision>
    </link>

    <link name='left_front_wheel_link'>
      <inertial>
        <mass value="0.0196261" />
        <origin rpy="0 1.57079 0" xyz="0 0 0" />
        <inertia ixx="0.00028435" ixy="0" ixz="0" iyy="0.00028435" iyz="0" izz="0.00054297" />
      </inertial>
      <visual name='left_front_wheel_visual'>
        <origin rpy="0 1.57079 0" xyz="0 0 0" />
        <geometry>
          <cylinder radius="0.235227" length="0.0886945" />
        </geometry>
      </visual>
      <collision name='left_front_wheel_collision'>
        <origin rpy="0 1.57079 0" xyz="0 0 0" />
        <geometry>
          <cylinder radius="0.235227" length="0.0886945" />
        </geometry>
      </collision>
    </link>

    <link name='left_steer_block_link'>
      <inertial>
        <mass value="0.00073514" />
	<origin rpy="0 0 0" xyz="0 0 0" />
        <inertia ixx="9.9e-07" ixy="0" ixz="0" iyy="9.4e-07" iyz="0" izz="1.1e-06" />
      </inertial>
      <visual name='left_steer_block_visual'>
      	<origin rpy="0 0 0" xyz="0 0 0" />
        <geometry>
          <box size="0.092365 0.096673 0.082207" />
        </geometry>
      </visual>
      <collision name='left_steer_block_collision'>
	<origin rpy="0 0 0" xyz="0 0 0" />
        <geometry>
          <box size="0.092365 0.096673 0.082207" />
        </geometry> 
      </collision>
    </link>

    <link name='right_steer_block_link'>
      <inertial>
        <mass value="0.00073514" />
	<origin rpy="0 0 0" xyz="0 0 0" />
        <inertia ixx="9.9e-07" ixy="0" ixz="0" iyy="9.4e-07" iyz="0" izz="1.1e-06" />
      </inertial>
      <visual name='right_steer_block_visual'>
	<origin rpy="0 0 0" xyz="0 0 0" />
        <geometry>
          <box size="0.092365 0.096673 0.082207" />
        </geometry>
      </visual>
      <collision name='right_steer_block_collision'>
	<origin rpy="0 0 0" xyz="0 0 0" />
        <geometry>
          <box size="0.092365 0.096673 0.082207" />
        </geometry>
      </collision>
    </link>

  <!-- joints -->
    <joint name='left_steer_block_joint' type='continuous'>
	<origin rpy="0 0 0" xyz="-0.31 0.457143 0" />
      <parent link="chassis_link" />
      <child link="left_steer_block_link" />
      <axis rpy ="0 0 0" xyz="0 0 1" />
      <limit effort="100" velocity="1000" />
      <joint_properties damping="1.0" friction="1.0" />
    </joint>

    <joint name='right_steer_block_joint' type='continuous'>
	<origin rpy="0 0 0" xyz="0.31 0.457143 0" />
      <parent link="chassis_link" />
      <child link="right_steer_block_link" />
      <axis rpy ="0 0 0" xyz="0 0 1" />
      <limit effort="100" velocity="1000" />
      <joint_properties damping="1.0" friction="1.0" />
    </joint>

    <joint name='left_rear_wheel_joint' type='continuous'>
      <origin rpy="0 0 0" xyz="-0.4 -0.742857 0" />
      <parent link="chassis_link" />
      <child link="left_rear_wheel_link" />
      <axis rpy ="0 0 0" xyz="1 0 0" />
      <limit effort="100" velocity="1000" />
      <joint_properties damping="1.0" friction="1.0" />
    </joint>

    <joint name='right_rear_wheel_joint' type='continuous'>
      <origin rpy="0 0 0" xyz="0.4 -0.742857 0" />
      <parent link="chassis_link" />
      <child link="right_rear_wheel_link" />
      <axis rpy ="0 0 0" xyz="1 0 0" />
      <limit effort="100" velocity="1000" />
      <joint_properties damping="1.0" friction="1.0" />
    </joint>

    <joint name='left_front_wheel_joint' type='continuous'>
      <origin rpy="0 0 0" xyz="-0.09 0 0" />
      <parent link="left_steer_block_link" />
      <child link="left_front_wheel_link" />
      <axis rpy ="0 0 0" xyz="1 0 0" />
      <limit effort="100" velocity="1000" />
      <joint_properties damping="1.0" friction="1.0" />
    </joint>

    <joint name='right_front_wheel_joint' type='continuous'>
      <origin rpy="0 0 0" xyz="0.09 0 0" />
      <parent link="right_steer_block_link" />
      <child link="right_front_wheel_link" />
      <axis rpy ="0 0 0" xyz="1 0 0" />
      <limit effort="100" velocity="1000" />
      <joint_properties damping="1.0" friction="1.0" />
    </joint>

<!-- hokuyo 2d laser scanner -->
    <joint name="hokuyo_laser_joint" type="fixed">
        <axis xyz="0 0 1" />
        <origin xyz="0 0 0.25" rpy="0 0 0"/>
        <parent link="chassis_link"/>
        <child link="hokuyo_laser_link"/>
    </joint>
     
    <link name="hokuyo_laser_link">
        <collision>
            <origin xyz="0 0 0" rpy="0 0 0"/>
            <geometry>
                <cylinder length="0.04" radius="0.045"/>
            </geometry>
        </collision>
        <visual>
            <origin xyz="0 0 0" rpy="0 0 0"/>
            <geometry>
                <cylinder length="0.04" radius="0.045"/>
            </geometry>
            <material name="iRobot/LightBlue"/>
        </visual>
        <inertial>
            <mass value="1e-5" />
            <origin xyz="0 0 0" rpy="0 0 0"/>
            <inertia ixx="1e-6" ixy="0" ixz="0" iyy="1e-6" iyz="0" izz="1e-6" />
        </inertial>
    </link>
    
    <gazebo reference="hokuyo_laser_link">
        <gravity>true</gravity>
        <sensor type="ray" name="head_hokuyo_sensor">
            <pose>0 0 0 0 0 0</pose>
            <visualize>true</visualize>
            <update_rate>40</update_rate>
            <ray>
                <scan>
                    <horizontal>
                        <samples>360</samples>
                        <resolution>1</resolution>
                        <min_angle>-3.14159</min_angle>
                        <max_angle>3.14159</max_angle>
                    </horizontal>
                </scan>
                <range>
                    <min>0.2</min>
                    <max>40</max>
                    <resolution>0.025</resolution>
                </range>
                <noise>
                    <type>gaussian</type>
                    <mean>0.0</mean>
                    <stddev>0.1</stddev>
                </noise>
            </ray>
            <plugin name="gazebo_ros_head_hokuyo_controller" filename="libgazebo_ros_laser.so">
                <robotNamespace></robotNamespace>
                <topicName>laser_scan</topicName>
                <frameName>hokuyo_laser_link</frameName>
            </plugin>      
        </sensor>
    </gazebo>
 

</robot>




